Propagate task results and exceptions via separate future instances if they are `await`-ed by the caller of `create_task()` in `PersistentTaskGroup`, in addition to invocation of task group exception handler.  Note that `await`-ing those futures hangs indefinitely in Python 3.6 but we don't fix it since Python 3.6 is EoL as of December 2021.
